<?xml version="1.0" ?>
<robot name="spam.urdf">

  <link name="world_axis1">
    <inertial>
      <mass value="0"/>
      <inertia ixx="0.0" ixy="0.0" ixz="0.0" iyy="0.0" iyz="0.0" izz="0.0"/>
    </inertial>
  </link>
    <link name="world_axis2">
    <inertial>
      <mass value="0"/>
      <inertia ixx="0.0" ixy="0.0" ixz="0.0" iyy="0.0" iyz="0.0" izz="0.0"/>
    </inertial>
  </link>

  <link name="spam">
    <contact>
      <lateral_friction value="0.5"/>
      <rolling_friction value="0.0"/>
      <contact_cfm value="0.0"/>
      <contact_erp value="1.0"/>
    </contact>
    <inertial>
      <origin rpy="0 0 0" xyz="0.0 0.02 0.0"/>
       <mass value=".5"/>
       <inertia ixx="1" ixy="0" ixz="0" iyy="1" iyz="0" izz="1"/>
    </inertial>
    <visual>
      <origin rpy="0 0 0" xyz="0 0 0"/>
      <geometry>
        <!-- <mesh filename="roboverse/envs/assets/objects/spam/spam.obj" scale="1 1 1"/> -->

        <!--<mesh filename="roboverse_assets/objects/spam/spam.obj" scale="1 1 1"/>-->

        <!-- <mesh filename="/Users/janner/Desktop/spam.obj" scale="1 1 1"/> -->
        <box size="2.45 1.95 1.95"/>
      </geometry>
      <!--<material name="white">
        <color rgba="1 1 1 1"/>
      </material>-->
    </visual>
    <collision>
      <origin rpy="0 0 0" xyz="0 0 0"/>
      <geometry>
	 	   <!-- <mesh filename="/Users/janner/Desktop/" scale=".05 .05 .05"/> -->
       <box size="2.45 1.95 1.95"/>
      </geometry>
    </collision>
  </link>

    <joint name="base_joint" type="planar">
        <parent link="world_axis1"/>
        <child link="world_axis2"/>
        <axis xyz="0 0 1"/>
    </joint>
    <joint name="base_joint2" type="prismatic">
        <parent link="world_axis2"/>
        <child link="spam"/>
        <axis xyz="0 0 1"/>
        <limit effort="0" lower="-0.1" upper="0.1" velocity="100"/>
    </joint>

</robot>