<?xml version="1.0" ?>
<robot name="spam.urdf">

  <link name="world_axis1">
    <inertial>
      <mass value="0"/>
      <inertia ixx="0.0" ixy="0.0" ixz="0.0" iyy="0.0" iyz="0.0" izz="0.0"/>
    </inertial>
  </link>

  <link name="world_axis2">
    <inertial>
      <mass value="0"/>
      <inertia ixx="0.0" ixy="0.0" ixz="0.0" iyy="0.0" iyz="0.0" izz="0.0"/>
    </inertial>
  </link>

    <!--
    <link name="world_axis3">
    <inertial>
      <mass value="0"/>
      <inertia ixx="0.0" ixy="0.0" ixz="0.0" iyy="0.0" iyz="0.0" izz="0.0"/>
    </inertial>
  </link>
  -->

  <link name="spam">
    <contact>
      <lateral_friction value="tmux"/> <!-- 0.5 -->
      <rolling_friction value="0.0"/>
      <contact_cfm value="0.0"/>
      <contact_erp value="1.0"/>

    </contact>
    <inertial>
      <origin rpy="0 0 0" xyz="0.0 0.02 0.0"/>
       <mass value=".5"/>
       <inertia ixx="1" ixy="0" ixz="0" iyy="1" iyz="0" izz="1"/>
    </inertial>
    <visual>
      <origin rpy="0 0 0" xyz="0 0 0"/>
      <geometry>
        <!--<mesh filename="roboverse_assets/objects/spam/spam.obj" scale="1 1 1"/>-->
        <box size="2.45 1.95 1.95"/>
      </geometry>
    </visual>
    <collision>
      <origin rpy="0 0 0" xyz="0 0 0"/>
      <geometry>
       <box size="2.45 1.95 1.95"/>
      </geometry>
    </collision>
  </link>

    <!-- x axis -->
    <joint name="base_joint" type="prismatic">
        <parent link="world_axis1"/>
        <child link="world_axis2"/>
        <axis xyz="1 0 0"/>
        <limit effort="0" lower="-100" upper="100" velocity="100"/>
    </joint>

    <!-- y axis -->
    <!--
    <joint name="base_joint_2" type="prismatic">
        <parent link="world_axis2"/>
        <child link="world_axis3"/>
        <axis xyz="0 0 1"/>
        <limit effort="0" lower="100" upper="100" velocity="100"/>
    </joint>
    -->

    <!-- z axis -->
    <joint name="base_joint3" type="prismatic">
        <parent link="world_axis2"/>
        <child link="spam"/>
        <axis xyz="0 1 0"/>
        <limit effort="0" lower="-100" upper="100" velocity="100"/>
    </joint>

</robot>