<?xml version="0.0" ?>
<robot name="bowl.urdf">

  <material name="yellow">
    <color rgba="1 1 0.4 1"/>
  </material>
  <material name="red">
    <color rgba="1 0 0 1"/>
  </material>
  <material name="blue">
    <color rgba=".17 .20 .38 1"/>
  </material>
  <material name="teal">
    <color rgba="0 .5 .5 1"/>
  </material>
  <material name="orange">
    <color rgba=".93 .6 .23 1"/>
  </material>

  <!-- <link name="world"/> -->

    <link name="world_axis1">
    <inertial>
      <mass value="0"/>
      <inertia ixx="0.0" ixy="0.0" ixz="0.0" iyy="0.0" iyz="0.0" izz="0.0"/>
    </inertial>
  </link>

  <link name="world_axis2">
    <inertial>
      <mass value="0"/>
      <inertia ixx="0.0" ixy="0.0" ixz="0.0" iyy="0.0" iyz="0.0" izz="0.0"/>
    </inertial>
  </link>


  <link name="lid">
    <!--<lateral_friction value="1.0"/>-->
    <lateral_friction value="1"/>
    <rolling_friction value="0.0"/>
    <contact_cfm value="0.0"/>
    <contact_erp value="1.0"/>
    <inertial>
      <origin rpy="0 0 0" xyz="0.0 0.0 -0.35"/>
       <mass value="1"/>
       <inertia ixx="1" ixy="0" ixz="0" iyy="1" iyz="0" izz="1"/>
    </inertial>
    <visual>
      <origin rpy="0 0 0" xyz="0 0 0"/>
      <geometry>
        <!--<cylinder radius="0.7" length=".05"/>-->
          <box size="1.05 1.05 .2"/>
      </geometry>
       <material name="blue"/>
    </visual>
    <collision>
      <origin rpy="0 0 0" xyz="0 0 0"/>
      <geometry>
          <!--<cylinder radius="0.7" length=".05"/>-->
          <box size="1.05 1.05 .1"/>

      </geometry>
    </collision>
  </link>

  <link name="handle">
    <lateral_friction value="1.0"/>
    <rolling_friction value="0.0"/>
    <contact_cfm value="0.0"/>
    <contact_erp value="1.0"/>
    <inertial>
      <origin rpy="0 0 0" xyz="0.0 0.0 0.0"/>
       <mass value="1"/> <!--<mass value="1"/>-->
       <inertia ixx="1" ixy="0" ixz="0" iyy="1" iyz="0" izz="1"/>
    </inertial>
    <visual>
      <origin rpy="0 0 0" xyz="0 0 0"/>
      <geometry>
        <box size="0.1 0.25 .3"/> <!--<box size="0.1 0.5 .3"/>-->
      </geometry>
       <material name="orange"/>
    </visual>
    <collision>
      <origin rpy="0 0 0" xyz="0 0 0"/>
      <geometry>
        <box size="0.1 0.25 .3"/>
      </geometry>
    </collision>
  </link>

      <!-- x axis -->
    <joint name="base_joint" type="prismatic">
        <parent link="world_axis1"/>
        <child link="world_axis2"/>
        <axis xyz="0 1 0"/>
        <limit effort="0" lower="-100" upper="100" velocity="100"/>
    </joint>

    <!-- z axis -->
    <joint name="base_joint3" type="prismatic">
        <parent link="world_axis2"/>
        <child link="lid"/>
        <axis xyz="0 0 1"/>
        <limit effort="0" lower="-100" upper="100" velocity="100"/>
    </joint>

  <joint name="handle_joint" type="fixed">
    <origin rpy="0 0 0" xyz="0 0 0.15"/>
    <parent link="lid"/>
    <child link="handle"/>
  </joint>

</robot>

